<?xml version="1.0" encoding="utf-8"?>
<!-- This URDF was automatically created by SolidWorks to URDF Exporter! Originally created by Stephen Brawner (brawner@gmail.com) 
     Commit Version: 1.6.0-4-g7f85cfe  Build Version: 1.6.7995.38578
     For more information, please see http://wiki.ros.org/sw_urdf_exporter -->
<robot
  name="follower">
  	<mujoco>
    	<compiler meshdir="./meshes"/>
        <!-- if you get : "Error: inertia must satisfy A + B >= C; use 'balanceinertia' to fix", add balanceinertia="true" to the compiler tag -->
        <!-- You can also add discardvisual="true" discard model elements that are purely visual and have no effect on the simulation. -->
	</mujoco>
  <link
    name="base_link">
    <inertial>
      <origin
        xyz="0.052562 0.0056915 0.0023276"
        rpy="0 0 0" />
      <mass
        value="0.024929" />
      <inertia
        ixx="3.8411E-05"
        ixy="-2.3161E-06"
        ixz="1.8015E-07"
        iyy="1.0987E-05"
        iyz="1.4265E-07"
        izz="4.9192E-05" />
    </inertial>
    <visual>
      <origin
        xyz="0 0 0"
        rpy="0 0 0" />
      <geometry>
        <mesh
          filename="package://follower/meshes/base_link.STL" />
      </geometry>
      <material
        name="">
        <color
          rgba="0.79216 0.81961 0.93333 1" />
      </material>
    </visual>
    <collision>
      <origin
        xyz="0 0 0"
        rpy="0 0 0" />
      <geometry>
        <mesh
          filename="package://follower/meshes/base_link.STL" />
      </geometry>
    </collision>
  </link>
  <link
    name="link_1">
    <inertial>
      <origin
        xyz="0.013486 5.2531E-05 0.0012698"
        rpy="0 0 0" />
      <mass
        value="0.006884" />
      <inertia
        ixx="1.2238E-06"
        ixy="6.4703E-09"
        ixz="-2.3562E-08"
        iyy="2.3942E-06"
        iyz="1.696E-10"
        izz="3.4892E-06" />
    </inertial>
    <visual>
      <origin
        xyz="0 0 0"
        rpy="0 0 0" />
      <geometry>
        <mesh
          filename="package://follower/meshes/link_1.STL" />
      </geometry>
      <material
        name="">
        <color
          rgba="0.79216 0.81961 0.93333 1" />
      </material>
    </visual>
    <collision>
      <origin
        xyz="0 0 0"
        rpy="0 0 0" />
      <geometry>
        <mesh
          filename="package://follower/meshes/link_1.STL" />
      </geometry>
    </collision>
  </link>
  <joint
    name="joint_1"
    type="revolute">
    <origin
      xyz="0.012 0 0.0409"
      rpy="0 0 0" />
    <parent
      link="base_link" />
    <child
      link="link_1" />
    <axis
      xyz="0 0 -1" />
    <limit
      lower="-3.14"
      upper="3.14"
      effort="0.5"
      velocity="100" />
  </joint>
  <link
    name="link_2">
    <inertial>
      <origin
        xyz="0.0053511 0.0209 0.054556"
        rpy="0 0 0" />
      <mass
        value="0.034312" />
      <inertia
        ixx="3.6363E-05"
        ixy="-6.3589E-11"
        ixz="-2.8972E-06"
        iyy="3.1918E-05"
        iyz="-2.4413E-10"
        izz="6.6452E-06" />
    </inertial>
    <visual>
      <origin
        xyz="0 0 0"
        rpy="0 0 0" />
      <geometry>
        <mesh
          filename="package://follower/meshes/link_2.STL" />
      </geometry>
      <material
        name="">
        <color
          rgba="0.79216 0.81961 0.93333 1" />
      </material>
    </visual>
    <collision>
      <origin
        xyz="0 0 0"
        rpy="0 0 0" />
      <geometry>
        <mesh
          filename="package://follower/meshes/link_2.STL" />
      </geometry>
    </collision>
  </link>
  <joint
    name="joint_2"
    type="revolute">
    <origin
      xyz="0 -0.0209 0.0154"
      rpy="0 0 0" />
    <parent
      link="link_1" />
    <child
      link="link_2" />
    <axis
      xyz="0 1 0" />
    <limit
      lower="-3.14"
      upper="3.14"
      effort="0.5"
      velocity="100" />
  </joint>
  <link
    name="link_3">
    <inertial>
      <origin
        xyz="-0.042737 0.01445 0.0029224"
        rpy="0 0 0" />
      <mass
        value="0.047925" />
      <inertia
        ixx="6.6886E-06"
        ixy="-5.4129E-11"
        ixz="1.8813E-07"
        iyy="2.0377E-05"
        iyz="1.4056E-11"
        izz="2.2914E-05" />
    </inertial>
    <visual>
      <origin
        xyz="0 0 0"
        rpy="0 0 0" />
      <geometry>
        <mesh
          filename="package://follower/meshes/link_3.STL" />
      </geometry>
      <material
        name="">
        <color
          rgba="0.79216 0.81961 0.93333 1" />
      </material>
    </visual>
    <collision>
      <origin
        xyz="0 0 0"
        rpy="0 0 0" />
      <geometry>
        <mesh
          filename="package://follower/meshes/link_3.STL" />
      </geometry>
    </collision>
  </link>
  <joint
    name="joint_3"
    type="revolute">
    <origin
      xyz="-0.0148 0.0065 0.1083"
      rpy="0 0 0" />
    <parent
      link="link_2" />
    <child
      link="link_3" />
    <axis
      xyz="0 1 0" />
    <limit
      lower="-3.14"
      upper="3.14"
      effort="0.5"
      velocity="100" />
  </joint>
  <link
    name="link_4">
    <inertial>
      <origin
        xyz="-0.010716 0.015442 1.2785E-06"
        rpy="0 0 0" />
      <mass
        value="0.0045392" />
      <inertia
        ixx="1.1212E-06"
        ixy="3.0962E-08"
        ixz="-4.9081E-11"
        iyy="4.3402E-07"
        iyz="-2.2314E-12"
        izz="1.2935E-06" />
    </inertial>
    <visual>
      <origin
        xyz="0 0 0"
        rpy="0 0 0" />
      <geometry>
        <mesh
          filename="package://follower/meshes/link_4.STL" />
      </geometry>
      <material
        name="">
        <color
          rgba="0.79216 0.81961 0.93333 1" />
      </material>
    </visual>
    <collision>
      <origin
        xyz="0 0 0"
        rpy="0 0 0" />
      <geometry>
        <mesh
          filename="package://follower/meshes/link_4.STL" />
      </geometry>
    </collision>
  </link>
  <joint
    name="joint_4"
    type="revolute">
    <origin
      xyz="-0.10048 5E-05 0.0026999"
      rpy="0 0 0" />
    <parent
      link="link_3" />
    <child
      link="link_4" />
    <axis
      xyz="0 1 0" />
    <limit
      lower="-3.14"
      upper="3.14"
      effort="0.5"
      velocity="100" />
  </joint>
  <link
    name="link_5">
    <inertial>
      <origin
        xyz="-0.026112 0.012312 0.00013105"
        rpy="0 0 0" />
      <mass
        value="0.013412" />
      <inertia
        ixx="1.9982E-06"
        ixy="1.0587E-06"
        ixz="4.6095E-08"
        iyy="6.1793E-06"
        iyz="-5.5047E-09"
        izz="6.2583E-06" />
    </inertial>
    <visual>
      <origin
        xyz="0 0 0"
        rpy="0 0 0" />
      <geometry>
        <mesh
          filename="package://follower/meshes/link_5.STL" />
      </geometry>
      <material
        name="">
        <color
          rgba="0.79216 0.81961 0.93333 1" />
      </material>
    </visual>
    <collision>
      <origin
        xyz="0 0 0"
        rpy="0 0 0" />
      <geometry>
        <mesh
          filename="package://follower/meshes/link_5.STL" />
      </geometry>
    </collision>
  </link>
  <joint
    name="joint_5"
    type="revolute">
    <origin
      xyz="-0.045 0.013097 0"
      rpy="0 0 0" />
    <parent
      link="link_4" />
    <child
      link="link_5" />
    <axis
      xyz="1 0 0" />
    <limit
      lower="-3.14"
      upper="3.14"
      effort="0.5"
      velocity="100" />
  </joint>
  <link
    name="link_6">
    <inertial>
      <origin
        xyz="-0.02507 0.0010817 -0.01414"
        rpy="0 0 0" />
      <mass
        value="0.012831" />
      <inertia
        ixx="1.5159E-06"
        ixy="3.156E-07"
        ixz="3.409E-08"
        iyy="3.449E-06"
        iyz="-3.8705E-09"
        izz="2.4565E-06" />
    </inertial>
    <visual>
      <origin
        xyz="0 0 0"
        rpy="0 0 0" />
      <geometry>
        <mesh
          filename="package://follower/meshes/link_6.STL" />
      </geometry>
      <material
        name="">
        <color
          rgba="0.79216 0.81961 0.93333 1" />
      </material>
    </visual>
    <collision>
      <origin
        xyz="0 0 0"
        rpy="0 0 0" />
      <geometry>
        <mesh
          filename="package://follower/meshes/link_6.STL" />
      </geometry>
    </collision>
  </link>
  <joint
    name="joint_6"
    type="revolute">
    <origin
      xyz="-0.01315 -0.0075 0.0145"
      rpy="0 0 0" />
    <parent
      link="link_5" />
    <child
      link="link_6" />
    <axis
      xyz="0 0 -1" />
    <limit
      lower="-2.45"
      upper="0.032"
      effort="0.5"
      velocity="100" />
  </joint>
</robot>